<mujoco model="hopper">
  <compiler angle="degree" coordinate="global" inertiafromgeom="true"/>
  <default>
    <joint armature="0" damping="1" limited="true"/>
    <geom conaffinity="1" condim="1" contype="1" margin="0.001" material="geom" rgba="0.8 0.6 .4 1" solimp=".8 .8 .01" solref=".02 1"/>
  </default>
  <option integrator="Euler" timestep="0.002"/>
  <worldbody>
    <light cutoff="100" diffuse="1 1 1" dir="-0 0 -1.3" directional="true" exponent="1" pos="0 0 1.3" specular=".1 .1 .1"/>
    <geom conaffinity="1" condim="3" name="floor" pos="0 0 -10" rgba="0.8 0.9 0.8 1" size="20 20 .125" type="plane" material="MatPlane"/>
    <body name="torso" pos="0 0 1.25">
      <joint armature="0" axis="1 0 0" damping="0" limited="false" name="rootx" pos="0 0 0" stiffness="0" type="slide"/>
      <joint armature="0" axis="0 0 1" damping="0" limited="false" name="rootz" pos="0 0 0" ref="1.25" stiffness="0" type="slide"/>
      <joint armature="0" axis="0 -1 0" damping="0" limited="false" name="rooty" pos="0 0 1.25" stiffness="0" type="hinge"/>
      <geom friction="0.9" pos="0 0 1.25" name="torso_geom" size="0.2 0.2 0.2" type="box"/>
      <body name="torso2" pos="0 0 0.85">
          <joint armature="0" axis="0 -1 0" damping="0" limited="false" name="j1" pos="0 0 1.05" stiffness="0" type="hinge"/>
          <geom friction="0.9" pos="0 0 0.85" name="torso_geom2" size="0.2 0.2 0.2" type="box"/>
          <body name="torso3" pos="0 0 0.35">
              <joint armature="0" axis="0 -1 0" damping="0" limited="false" name="j2" pos="0 0 0.65" stiffness="0" type="hinge"/>
              <geom friction="0.9" pos="0 0 0.35" name="torso_geom3" size="0.1 0.1 0.3" type="box"/>
              <body name="torso4" pos="0 0 0.0">
                  <joint armature="0" axis="0 -1 0" damping="0" limited="false" name="j3" pos="0 0 0.05" stiffness="0" type="hinge"/>
                  <geom friction="0.9" pos="0 0 0.0" name="torso_geom4" size="0.3 0.1 0.05" type="box"/>
              </body>
          </body>
      </body>
    </body>
  </worldbody>
    <asset>
        <texture type="skybox" builtin="gradient" rgb1=".4 .5 .6" rgb2="0 0 0"
            width="100" height="100"/>        
        <texture builtin="flat" height="1278" mark="cross" markrgb="1 1 1" name="texgeom" random="0.01" rgb1="0.8 0.6 0.4" rgb2="0.8 0.6 0.4" type="cube" width="127"/>
        <texture builtin="checker" height="100" name="texplane" rgb1="0 0 0" rgb2="0.8 0.8 0.8" type="2d" width="100"/>
        <material name="MatPlane" reflectance="0.5" shininess="1" specular="1" texrepeat="60 60" texture="texplane"/>
        <material name="geom" texture="texgeom" texuniform="true"/>
    </asset>
</mujoco>